<?xml version="1.0" ?>
<sdf version="1.10">
    <world name="light_seeking_world">
        <physics name="1ms" type="ignored">
            <max_step_size>0.001</max_step_size>
            <real_time_factor>1.0</real_time_factor>
        </physics>
        <plugin
            filename="gz-sim-physics-system"
            name="gz::sim::systems::Physics">
        </plugin>
        <plugin
            filename="gz-sim-user-commands-system"
            name="gz::sim::systems::UserCommands">
        </plugin>
        <plugin
            filename="gz-sim-scene-broadcaster-system"
            name="gz::sim::systems::SceneBroadcaster">
        </plugin>
    
        <plugin filename="gz-sim-imu-system"
                name="gz::sim::systems::Imu">
        </plugin>
        <plugin filename="gz-sim-contact-system"
                name="gz::sim::systems::Contact">
        </plugin>

       
        <!-- Light Path -->
        <light type="point" name="light_1">
            <pose>5.2 0.2 1 0 0 0</pose>
            <diffuse>1 1 1 1</diffuse>
            <specular>0.3 0.3 0.3 1</specular>
            <attenuation>
                <range>4.0</range>
                <constant>0.4</constant>
                <linear>0.15</linear>
                <quadratic>0.008</quadratic>
            </attenuation>
        </light>

        <light type="point" name="light_2">
            <pose>4.1 2.7 1 0 0 0</pose>
            <diffuse>1 1 1 1</diffuse>
            <specular>0.3 0.3 0.3 1</specular>
            <attenuation>
                <range>4.0</range>
                <constant>0.4</constant>
                <linear>0.15</linear>
                <quadratic>0.008</quadratic>
            </attenuation>
        </light>

        <light type="point" name="light_3">
            <pose>2.7 4.4 1 0 0 0</pose>
            <diffuse>1 1 1 1</diffuse>
            <specular>0.3 0.3 0.3 1</specular>
            <attenuation>
                <range>4.0</range>
                <constant>0.4</constant>
                <linear>0.15</linear>
                <quadratic>0.008</quadratic>
            </attenuation>
        </light>

        <light type="point" name="light_4">
            <pose>-0.1 5.3 1 0 0 0</pose>
            <diffuse>1 1 1 1</diffuse>
            <specular>0.3 0.3 0.3 1</specular>
            <attenuation>
                <range>4.0</range>
                <constant>0.4</constant>
                <linear>0.15</linear>
                <quadratic>0.008</quadratic>
            </attenuation>
        </light>

        <light type="point" name="light_5">
            <pose>-2.0 4.5 0.8 0 0 0</pose>
            <diffuse>1 1 1 1</diffuse>
            <specular>0.3 0.3 0.3 1</specular>
            <attenuation>
                <range>4.0</range>
                <constant>0.4</constant>
                <linear>0.15</linear>
                <quadratic>0.008</quadratic>
            </attenuation>
        </light>

        <light type="point" name="light_6">
            <pose>-4.4 2.4 1 0 0 0</pose>
            <diffuse>1 1 1 1</diffuse>
            <specular>0.3 0.3 0.3 1</specular>
            <attenuation>
                <range>4.0</range>
                <constant>0.4</constant>
                <linear>0.15</linear>
                <quadratic>0.008</quadratic>
            </attenuation>
        </light>

        <light type="point" name="light_7">
            <pose>-5.1 -0.3 1 0 0 0</pose>
            <diffuse>1 1 1 1</diffuse>
            <specular>0.3 0.3 0.3 1</specular>
            <attenuation>
                <range>4.0</range>
                <constant>0.4</constant>
                <linear>0.15</linear>
                <quadratic>0.008</quadratic>
            </attenuation>
        </light>

        <light type="point" name="light_8">
            <pose>-4.3 -2.8 1 0 0 0</pose>
            <diffuse>1 1 1 1</diffuse>
            <specular>0.3 0.3 0.3 1</specular>
            <attenuation>
                <range>4.0</range>
                <constant>0.4</constant>
                <linear>0.15</linear>
                <quadratic>0.008</quadratic>
            </attenuation>
        </light>

        <light type="point" name="light_9">
            <pose>-2.4 -4.3 1 0 0 0</pose>
            <diffuse>1 1 1 1</diffuse>
            <specular>0.3 0.3 0.3 1</specular>
            <attenuation>
                <range>4.0</range>
                <constant>0.4</constant>
                <linear>0.15</linear>
                <quadratic>0.008</quadratic>
            </attenuation>
        </light>

        <light type="point" name="light_10">
            <pose>0.2 -5.2 1 0 0 0</pose>
            <diffuse>1 1 1 1</diffuse>
            <specular>0.3 0.3 0.3 1</specular>
            <attenuation>
                <range>4.0</range>
                <constant>0.4</constant>
                <linear>0.15</linear>
                <quadratic>0.008</quadratic>
            </attenuation>
        </light>

        <light type="point" name="light_11">
            <pose>2.5 -4.5 1 0 0 0</pose>
            <diffuse>1 1 1 1</diffuse>
            <specular>0.3 0.3 0.3 1</specular>
            <attenuation>
                <range>4.0</range>
                <constant>0.4</constant>
                <linear>0.15</linear>
                <quadratic>0.008</quadratic>
            </attenuation>
        </light>

        <light type="point" name="light_12">
            <pose>4.4 -2.7 1 0 0 0</pose>
            <diffuse>1 1 1 1</diffuse>
            <specular>0.3 0.3 0.3 1</specular>
            <attenuation>
                <range>4.0</range>
                <constant>0.4</constant>
                <linear>0.15</linear>
                <quadratic>0.008</quadratic>
            </attenuation>
        </light>



        <!-- Ground Plane -->
        <model name="ground_plane">
            <static>true</static>
            <link name="link">
                <collision name="collision">
                    <geometry>
                        <plane>
                            <normal>0 0 1</normal>
                        </plane>
                    </geometry>
                </collision>
                <visual name="visual">
                    <geometry>
                        <plane>
                            <normal>0 0 1</normal>
                            <size>100 100</size>
                        </plane>
                    </geometry>
                    <material>
                        <ambient>0.8 0.8 0.8 1</ambient>
                        <diffuse>0.8 0.8 0.8 1</diffuse>
                        <specular>0.8 0.8 0.8 1</specular>
                    </material>
                </visual>
            </link>
        </model>

        <!-- Obstacles -->
        <model name="obstacle_1">
            <static>true</static>
            <link name="link">
                <pose>4.0 2.5 0 0 0 0</pose>
                <collision name="collision">
                    <geometry>
                        <cylinder>
                            <radius>0.5</radius>
                            <length>1.0</length>
                        </cylinder>
                    </geometry>
                </collision>
                <sensor name='sensor_contact' type='contact'>
                    <contact>
                        <collision>collision</collision>
                    </contact>
                </sensor>
                <visual name="visual">
                    <geometry>
                        <cylinder>
                            <radius>0.5</radius>
                            <length>1.0</length>
                        </cylinder>
                    </geometry>
                    <material>
                        <ambient>1 0 0 1</ambient>
                        <diffuse>1 0 0 1</diffuse>
                    </material>
                </visual>
            </link>
        </model>

        <model name="obstacle_2">
            <static>true</static>
            <link name="link">
                <pose>-2.0 -4.0 0 0 0 0</pose>
                <collision name="collision">
                    <geometry>
                        <box>
                            <size>1.0 1.0 1.0</size>
                        </box>
                    </geometry>
                </collision>
                <sensor name='sensor_contact' type='contact'>
                    <contact>
                        <collision>collision</collision>
                    </contact>
                </sensor>
                <visual name="visual">
                    <geometry>
                        <box>
                            <size>1.0 1.0 1.0</size>
                        </box>
                    </geometry>
                    <material>
                        <ambient>0 1 0 1</ambient>
                        <diffuse>0 1 0 1</diffuse>
                    </material>
                </visual>
            </link>
             <plugin filename="gz-sim-touchplugin-system"
                    name="gz::sim::systems::TouchPlugin">
                <target>light_seeking_robot</target> 
                <namespace>wall</namespace>
                <enabled>true</enabled>
                  <time>0.1</time>
            </plugin>
        </model>

       


        <!-- Robot Model -->
        <model name='light_seeking_robot' canonical_link='chassis'>
            <pose relative_to='world'>5.0 0 0 0 0 1.57</pose>
            <frame name="lidar_frame" attached_to='chassis'>
                <pose>0.8 0 0.5 0 0 0</pose>
            </frame>
                <link name='chassis'>
                <pose relative_to='__model__'>0.5 0 0.4 0 0 0</pose>
                <inertial> <!--inertial properties of the link mass, inertia matix-->
                    <mass>1.14395</mass>
                    <inertia>
                        <ixx>0.095329</ixx>
                        <ixy>0</ixy>
                        <ixz>0</ixz>
                        <iyy>0.381317</iyy>
                        <iyz>0</iyz>
                        <izz>0.476646</izz>
                    </inertia>
                </inertial>

                <visual name='visual'>
                    <geometry>
                        <box>
                            <size>2.0 1.0 0.5</size>
                        </box>
                    </geometry>
                    <!--let's add color to our link-->
                    <material>
                        <ambient>0.0 0.0 1.0 1</ambient>
                        <diffuse>0.0 0.0 1.0 1</diffuse>
                        <specular>0.0 0.0 1.0 1</specular>
                    </material>
                </visual>
                <collision name='collision'>
                    <geometry>
                        <box>
                            <size>2.0 1.0 0.5</size>
                        </box>
                    </geometry>
                </collision>

                <sensor name="imu_sensor" type="imu">
                    <always_on>1</always_on>
                    <update_rate>1</update_rate>
                    <visualize>true</visualize>
                    <topic>imu</topic>
                </sensor>
                
                <sensor name='gpu_lidar' type='gpu_lidar'>"
                    <pose relative_to='lidar_frame'>0 0 0 0 0 0</pose>
                    <topic>lidar</topic>
                    <update_rate>10</update_rate>
                    <ray>
                        <scan>
                            <horizontal>
                                <samples>640</samples>
                                <resolution>1</resolution>
                                <min_angle>-1.396263</min_angle>
                                <max_angle>1.396263</max_angle>
                            </horizontal>
                            <vertical>
                                <samples>1</samples>
                                <resolution>0.01</resolution>
                                <min_angle>0</min_angle>
                                <max_angle>0</max_angle>
                            </vertical>
                        </scan>
                        <range>
                            <min>0.08</min>
                            <max>10.0</max>
                            <resolution>0.01</resolution>
                        </range>
                    </ray>
                    <always_on>1</always_on>
                    <visualize>true</visualize>
                </sensor>

                <!-- light sensor -->

                <sensor name="camera" type="camera">
                    <pose relative_to="lidar_frame">0.5 0 0.3 0 0 0</pose>
                    <visualize>true</visualize>
                    <update_rate>30</update_rate>
                    <camera>
                        <horizontal_fov>1.5708</horizontal_fov> <!-- 90 degrees -->
                        <image>
                            <format>R8G8B8</format>
                            <width>640</width>
                            <height>480</height>
                        </image>
                        <clip>
                            <near>0.1</near>
                            <far>100</far>
                        </clip>
                    </camera>
                    <plugin filename="libgazebo_ros_camera.so" name="camera_plugin">
                        <ros>
                            <namespace>camera</namespace>
                            <topic_name>image_raw</topic_name>
                            <frame_name>camera_optical</frame_name>
                        </ros>
                        <format>RGB8</format>
                    </plugin>
                    
                </sensor>

            </link>

           <frame name="camera_optical" attached_to="chassis">
                <pose relative_to="lidar_frame">0.5 0 0.3 0 -1.5708 1.5708</pose>
            </frame>

            <!-- left wheel -->
            <link name='left_wheel'>
                <pose relative_to="chassis">-0.5 0.6 0 -1.5707 0 0</pose>
                <inertial>
                    <mass>1</mass>
                    <inertia>
                        <ixx>0.043333</ixx>
                        <ixy>0</ixy>
                        <ixz>0</ixz>
                        <iyy>0.043333</iyy>
                        <iyz>0</iyz>
                        <izz>0.08</izz>
                    </inertia>
                </inertial>
            
                <visual name='visual'>
                    <geometry>
                        <cylinder>
                            <radius>0.4</radius>
                            <length>0.2</length>
                        </cylinder>
                    </geometry>
                    <material>
                        <ambient>1.0 0.0 0.0 1</ambient>
                        <diffuse>1.0 0.0 0.0 1</diffuse>
                        <specular>1.0 0.0 0.0 1</specular>
                    </material>
                </visual>
                <collision name='collision'>
                    <geometry>
                        <cylinder>
                            <radius>0.4</radius>
                            <length>0.2</length>
                        </cylinder>
                    </geometry>
                </collision>
            </link>
            <!--The same as left wheel but with different position-->
                <link name='right_wheel'>
                    <pose relative_to="chassis">-0.5 -0.6 0 -1.5707 0 0</pose> <!--angles are in radian-->
                    <inertial>
                        <mass>1</mass>
                        <inertia>
                            <ixx>0.043333</ixx>
                            <ixy>0</ixy>
                            <ixz>0</ixz>
                            <iyy>0.043333</iyy>
                            <iyz>0</iyz>
                            <izz>0.08</izz>
                        </inertia>
                    </inertial>
                    <visual name='visual'>
                        <geometry>
                            <cylinder>
                                <radius>0.4</radius>
                                <length>0.2</length>
                            </cylinder>
                        </geometry>
                        <material>
                            <ambient>1.0 0.0 0.0 1</ambient>
                            <diffuse>1.0 0.0 0.0 1</diffuse>
                            <specular>1.0 0.0 0.0 1</specular>
                        </material>
                    </visual>
                    <collision name='collision'>
                        <geometry>
                            <cylinder>
                                <radius>0.4</radius>
                                <length>0.2</length>
                            </cylinder>
                        </geometry>
                    </collision>
                </link>
            <frame name="caster_frame" attached_to='chassis'>
                <pose>0.8 0 -0.2 0 0 0</pose>
            </frame>
            <!--caster wheel-->
                <link name='caster'>
                    <pose relative_to='caster_frame'/>
                    <inertial>
                        <mass>1</mass>
                        <inertia>
                            <ixx>0.016</ixx>
                            <ixy>0</ixy>
                            <ixz>0</ixz>
                            <iyy>0.016</iyy>
                            <iyz>0</iyz>
                            <izz>0.016</izz>
                        </inertia>
                    </inertial>
                    <visual name='visual'>
                        <geometry>
                            <sphere>
                                <radius>0.2</radius>
                            </sphere>
                        </geometry>
                        <material>
                            <ambient>0.0 1 0.0 1</ambient>
                            <diffuse>0.0 1 0.0 1</diffuse>
                            <specular>0.0 1 0.0 1</specular>
                        </material>
                    </visual>
                    <collision name='collision'>
                        <geometry>
                            <sphere>
                                <radius>0.2</radius>
                            </sphere>
                        </geometry>
                    </collision>
                </link>
            <joint name='left_wheel_joint' type='revolute'>
                <pose relative_to='left_wheel'/>
                    <parent>chassis</parent>
                    <child>left_wheel</child>
                    <axis>
                    <xyz expressed_in='__model__'>0 1 0</xyz> <!--can be defined as any frame or even arbitrary frames-->
                    <limit>
                        <lower>-1.79769e+308</lower>    <!--negative infinity-->
                        <upper>1.79769e+308</upper>     <!--positive infinity-->
                    </limit>
                </axis>
            </joint>
                <joint name='right_wheel_joint' type='revolute'>
                <pose relative_to='right_wheel'/>
                <parent>chassis</parent>
                <child>right_wheel</child>
                <axis>
                    <xyz expressed_in='__model__'>0 1 0</xyz>
                    <limit>
                        <lower>-1.79769e+308</lower>    <!--negative infinity-->
                        <upper>1.79769e+308</upper>     <!--positive infinity-->
                    </limit>
                </axis>
            </joint>
            <joint name='caster_wheel' type='ball'>
                <parent>chassis</parent>
                <child>caster</child>
            </joint>

            

          <plugin
            filename="gz-sim-diff-drive-system"
            name="gz::sim::systems::DiffDrive">
            <left_joint>left_wheel_joint</left_joint>
            <right_joint>right_wheel_joint</right_joint>
            <wheel_separation>1.2</wheel_separation>
            <wheel_radius>0.4</wheel_radius>
            <odom_publish_frequency>1</odom_publish_frequency>
            <topic>cmd_vel</topic>
        </plugin>

        <plugin filename="gz-sim-triggered-publisher-system"
                name="gz::sim::systems::TriggeredPublisher">
            <input type="gz.msgs.Boolean" topic="/wall/touched">
                <match>data: true</match>
            </input>
            <output type="gz.msgs.Twist" topic="/cmd_vel">
                linear: {x: 0.0}, angular: {z: 0.0}
            </output>
        </plugin>
           

            
        </model>
    </world>
</sdf>